Workbook

Sheet Summary
A1: Subgroup | B1: Total | C1: UP_in_KO_aging | D1: DOWN_in_KO_aging
A2: Subgroup1_Aging-specific#1 | B2: =COUNTA('Subgroup1_Aging-specific#1'!A:A)-1 -> 757 | C2: =COUNTIF('Subgroup1_Aging-specific#1'!C:C,"UP") -> 407 | D2: =COUNTIF('Subgroup1_Aging-specific#1'!C:C,"DOWN") -> 350
A3: Subgroup2_Aging-specific#2 | B3: =COUNTA('Subgroup2_Aging-specific#2'!A:A)-1 -> 28 | C3: =COUNTIF('Subgroup2_Aging-specific#2'!C:C,"UP") -> 27 | D3: =COUNTIF('Subgroup2_Aging-specific#2'!C:C,"DOWN") -> 1
A4: Subgroup3_Aging_and_early_pancr | B4: =COUNTA(Subgroup3_Aging_and_early_pancr!A:A)-1 -> 162 | C4: =COUNTIF(Subgroup3_Aging_and_early_pancr!C:C,"UP") -> 54 | D4: =COUNTIF(Subgroup3_Aging_and_early_pancr!C:C,"DOWN") -> 108
A5: Subgroup4_Aging_and_longstandin | B5: =COUNTA(Subgroup4_Aging_and_longstandin!A:A)-1 -> 31 | C5: =COUNTIF(Subgroup4_Aging_and_longstandin!C:C,"UP") -> 17 | D5: =COUNTIF(Subgroup4_Aging_and_longstandin!C:C,"DOWN") -> 14
A6: Subgroup5_Pancreatitis-specific | B6: =COUNTA('Subgroup5_Pancreatitis-specific'!A:A)-1 -> 3 | C6: =COUNTIF('Subgroup5_Pancreatitis-specific'!C:C,"UP") -> 2 | D6: =COUNTIF('Subgroup5_Pancreatitis-specific'!C:C,"DOWN") -> 1
A7: Subgroup6_Longstanding_chronic_ | B7: =COUNTA(Subgroup6_Longstanding_chronic_!A:A)-1 -> 161 | C7: =COUNTIF(Subgroup6_Longstanding_chronic_!C:C,"UP") -> 152 | D7: =COUNTIF(Subgroup6_Longstanding_chronic_!C:C,"DOWN") -> 9
A8: Subgroup7_Longstanding_chronic_ | B8: =COUNTA(Subgroup7_Longstanding_chronic_!A:A)-1 -> 914 | C8: =COUNTIF(Subgroup7_Longstanding_chronic_!C:C,"UP") -> 562 | D8: =COUNTIF(Subgroup7_Longstanding_chronic_!C:C,"DOWN") -> 352
A10: Note: Subgroups classified using the direction-match criterion (dirmatch) across KO_aging, WT_aging, 14m genotype (WT vs KO), and 6m genotype (WT vs KO) comparisons. A candidate 8th subgroup (pancreatitis-specific#2) was evaluated but contained no co-occurring DEGs, so the final classification retains 7 subgroups.

Sheet Subgroup1_Aging-specific#1
A1: Ensembl_ID | B1: Symbol | C1: KO_aging_direction | D1: KO_aging_log2FC | E1: KO_aging_padj | F1: WT_aging_direction | G1: WT_aging_log2FC | H1: WT_aging_padj | I1: 14m_genotype_direction | J1: m14_genotype_log2FC | K1: m14_genotype_padj | L1: 6m_genotype_direction | M1: m6_genotype_log2FC | N1: m6_genotype_padj
A2: ENSMUSG00000096525 | B2: Gm2663 | C2: DOWN | D2: -2.6195048 | E2: 1.3982629e-60 | F2: DOWN | G2: -5.7623948 | H2: 6.0162819e-05 | I2: UP | J2: 11.878836 | K2: 2.2470525e-28 | L2: UP | M2: 8.7229271 | N2: 7.0698981e-175
A3: ENSMUSG00000025270 | B3: Alas2 | C3: DOWN | D3: -2.7823134 | E3: 1.4261248e-20 | F3: DOWN | G3: -2.1128461 | H3: 9.8650568e-06
A4: ENSMUSG00000025283 | B4: Sat1 | C4: DOWN | D4: -2.5930719 | E4: 7.6384306e-34 | F4: DOWN | G4: -2.1644862 | H4: 1.0043369e-11
A5: ENSMUSG00000025351 | B5: Cd63 | C5: DOWN | D5: -3.2227393 | E5: 9.9902252e-93 | F5: DOWN | G5: -4.3702475 | H5: 1.6050098e-62
A6: ENSMUSG00000025544 | B6: Tm9sf2 | C6: DOWN | D6: -2.5187661 | E6: 1.6438008e-43 | F6: DOWN | G6: -2.2007569 | H6: 2.9059718e-14
A7: ENSMUSG00000025630 | B7: Hprt1 | C7: DOWN | D7: -3.570823 | E7: 4.7755111e-21 | F7: DOWN | G7: -2.6801178 | H7: 2.763724e-09
A8: ENSMUSG00000025869 | B8: Nop16 | C8: DOWN | D8: -2.0900917 | E8: 4.7801498e-14 | F8: DOWN | G8: -2.9630649 | H8: 4.8586796e-11
A9: ENSMUSG00000025889 | B9: Snca | C9: DOWN | D9: -2.2925742 | E9: 3.3916492e-07 | F9: DOWN | G9: -2.8961677 | H9: 0.0022576357
A10: ENSMUSG00000025894 | B10: Aasdhppt | C10: DOWN | D10: -2.5922974 | E10: 4.4358588e-14 | F10: DOWN | G10: -2.5462589 | H10: 6.1121798e-07
A11: ENSMUSG00000025903 | B11: Lypla1 | C11: DOWN | D11: -2.4566271 | E11: 3.5188124e-22 | F11: DOWN | G11: -2.0301859 | H11: 1.015286e-05
A12: ENSMUSG00000025933 | B12: Tmem14a | C12: DOWN | D12: -3.3926553 | E12: 0.0014018181 | F12: DOWN | G12: -4.5408651 | H12: 0.011861451
A13: ENSMUSG00000025934 | B13: Gsta3 | C13: DOWN | D13: -2.4548731 | E13: 2.4637972e-14 | F13: DOWN | G13: -2.215064 | H13: 2.4707594e-08
A14: ENSMUSG00000025940 | B14: Tmem70 | C14: DOWN | D14: -2.1390295 | E14: 1.1696562e-12 | F14: DOWN | G14: -2.6231985 | H14: 7.0175591e-08
... A39: ENSMUSG00000024258 | B39: Polr2d | C39: DOWN | D39: -2.1895956 | E39: 6.7610453e-05 | F39: DOWN | G39: -2.9331036 | H39: 0.00027515525
A40: ENSMUSG00000024359 | B40: Hspa9 | C40: DOWN | D40: -2.1264033 | E40: 4.1951127e-47 | F40: DOWN | G40: -2.2438869 | H40: 3.8486335e-16 | I40: UP | J40: 1.2756997 | K40: 2.1438226e-08 | L40: UP | M40: 1.0339906 | N40: 3.6955008e-05
A41: ENSMUSG00000024645 | B41: Timm21 | C41: DOWN | D41: -2.8958488 | E41: 1.0784239e-13 | F41: DOWN | G41: -2.3842485 | H41: 0.0043043801
A42: ENSMUSG00000022972 | B42: Cfap298 | C42: DOWN | D42: -2.066397 | E42: 1.6075978e-07 | F42: DOWN | G42: -2.7367588 | H42: 4.4821206e-07
A43: ENSMUSG00000026234 | B43: Nucleolin | C43: DOWN | D43: -2.2555335 | E43: 0.00015322816 | F43: DOWN | G43: -2.5584971 | H43: 6.3825536e-22
A44: ENSMUSG00000026248 | B44: Mrpl44 | C44: DOWN | D44: -2.2921562 | E44: 5.5746915e-11 | F44: DOWN | G44: -3.1824138 | H44: 1.5966429e-07
A45: ENSMUSG00000026377 | B45: Nifk | C45: DOWN | D45: -2.5358947 | E45: 1.0822969e-19 | F45: DOWN | G45: -2.0465288 | H45: 5.4166493e-06
A46: ENSMUSG00000028029 | B46: Aimp1 | C46: DOWN | D46: -2.1814819 | E46: 5.2738874e-16 | F46: DOWN | G46: -2.7852232 | H46: 4.9205605e-14
A47: ENSMUSG00000028044 | B47: Cks1b | C47: DOWN | D47: -2.3706573 | E47: 3.8430152e-09 | F47: DOWN | G47: -3.2803061 | H47: 4.3216841e-06
A48: ENSMUSG00000028111 | B48: Ctsk | C48: DOWN | D48: -2.8019144 | E48: 1.3319972e-12 | F48: DOWN | G48: -2.680888 | H48: 0.043760295 | L48: UP | M48: 1.9113446 | N48: 0.00056680766
A49: ENSMUSG00000028140 | B49: Mrpl9 | C49: DOWN | D49: -2.4030758 | E49: 9.5684151e-10 | F49: DOWN | G49: -2.3232217 | H49: 2.6524545e-06
A50: ENSMUSG00000028156 | B50: Eif4e | C50: DOWN | D50: -2.4340313 | E50: 3.4350709e-27 | F50: DOWN | G50: -2.3074751 | H50: 1.7132218e-09
A51: ENSMUSG00000028223 | B51: Decr1 | C51: DOWN | D51: -2.3167938 | E51: 2.4635054e-19 | F51: DOWN | G51: -2.429946 | H51: 1.1725452e-08
A52: ENSMUSG00000028247 | B52: Coq3 | C52: DOWN | D52: -2.3002627 | E52: 5.3795281e-09 | F52: DOWN | G52: -2.3484044 | H52: 0.00016557453
A53: ENSMUSG00000028293 | B53: Slc35a1 | C53: DOWN | D53: -2.2303035 | E53: 6.1285796e-11 | F53: DOWN | G53: -2.082061 | H53: 0.0001662334
A54: ENSMUSG00000028010 | B54: Gar1 | C54: DOWN | D54: -2.2003038 | E54: 3.6551696e-11 | F54: DOWN | G54: -2.5581683 | H54: 1.5446867e-05
A55: ENSMUSG00000028295 | B55: Smim8 | C55: DOWN | D55: -2.7279703 | E55: 2.8987523e-06 | F55: DOWN | G55: -3.4043598 | H55: 0.00036079886
A56: ENSMUSG00000028343 | B56: Erp44 | C56: DOWN | D56: -2.1290515 | E56: 4.4718724e-24 | F56: DOWN | G56: -2.2663223 | H56: 1.2154183e-17
A57: ENSMUSG00000028367 | B57: Txn1 | C57: DOWN | D57: -3.8732152 | E57: 3.2542846e-55 | F57: DOWN | G57: -4.6280949 | H57: 5.3260238e-32
A58: ENSMUSG00000028378 | B58: Ptgr1 | C58: DOWN | D58: -3.0383046 | E58: 2.6494986e-11 | F58: DOWN | G58: -3.2355542 | H58: 0.0016855066
A59: ENSMUSG00000028394 | B59: Pole3 | C59: DOWN | D59: -2.4397565 | E59: 2.9662657e-13 | F59: DOWN | G59: -2.764366 | H59: 3.8987695e-08
A60: ENSMUSG00000028398 | B60: Dmac1 | C60: DOWN | D60: -2.0588988 | E60: 4.1930008e-08 | F60: DOWN | G60: -2.6390584 | H60: 1.0799923e-05
... A82: ENSMUSG00000027637 | B82: Rab5if | C82: DOWN | D82: -2.6848605 | E82: 5.5824851e-16 | F82: DOWN | G82: -2.6324902 | H82: 4.0516236e-10
A83: ENSMUSG00000027801 | B83: Tm4sf4 | C83: DOWN | D83: -2.0654738 | E83: 3.9437848e-20 | F83: DOWN | G83: -2.1016814 | H83: 6.0218756e-05 | I83: UP | J83: 1.6304233 | K83: 0.00011260579 | L83: UP | M83: 1.4699963 | N83: 1.8234192e-05
A84: ENSMUSG00000027822 | B84: Slc33a1 | C84: DOWN | D84: -2.9780546 | E84: 7.4124325e-35 | F84: DOWN | G84: -2.9175044 | H84: 1.0008151e-15
A85: ENSMUSG00000027835 | B85: Pdcd10 | C85: DOWN | D85: -2.3449022 | E85: 3.1845561e-09 | F85: DOWN | G85: -3.0021862 | H85: 5.0325282e-07
...

Sheet Subgroup2_Aging-specific#2
A1: Ensembl_ID | B1: Symbol | C1: KO_aging_direction | D1: KO_aging_log2FC | E1: KO_aging_padj | F1: WT_aging_direction | G1: WT_aging_log2FC | H1: WT_aging_padj | I1: 14m_genotype_direction | J1: m14_genotype_log2FC | K1: m14_genotype_padj | L1: 6m_genotype_direction | M1: m6_genotype_log2FC | N1: m6_genotype_padj
A2: ENSMUSG00000075232 | B2: Amd1 | C2: DOWN | D2: -2.7557144 | E2: 1.60223e-23 | F2: DOWN | G2: -2.0019951 | H2: 1.0878635e-09 | I2: DOWN | J2: -1.256429 | K2: 0.00090655818
A3: ENSMUSG00000026609 | B3: Ush2a | C3: UP | D3: 6.6263892 | E3: 3.8675131e-21 | F3: UP | G3: 4.2900635 | H3: 0.0071414294 | I3: UP | J3: 1.8916605 | K3: 0.00043904717
A4: ENSMUSG00000055567 | B4: Unc80 | C4: UP | D4: 5.0903871 | E4: 2.6177681e-44 | F4: UP | G4: 2.3640959 | H4: 0.025028224 | I4: UP | J4: 2.4133183 | K4: 6.1783814e-07
A5: ENSMUSG00000058153 | B5: Sez6l | C5: UP | D5: 3.6523652 | E5: 3.402759e-44 | F5: UP | G5: 2.7164207 | H5: 6.8870588e-06 | I5: UP | J5: 1.2479419 | K5: 0.0099948167
A6: ENSMUSG00000041592 | B6: Sdk2 | C6: UP | D6: 5.2420647 | E6: 1.2990369e-69 | F6: UP | G6: 4.341585 | H6: 1.720753e-05 | I6: UP | J6: 2.2690524 | K6: 7.4405436e-09
A7: ENSMUSG00000006586 | B7: Runx1t1 | C7: UP | D7: 2.9215086 | E7: 1.8038627e-12 | F7: UP | G7: 2.3502933 | H7: 0.01458995 | I7: UP | J7: 1.2369772 | K7: 0.019394976
A8: ENSMUSG00000085925 | B8: Rtl1 | C8: UP | D8: 5.8405785 | E8: 5.5505286e-15 | F8: UP | G8: 5.3979001 | H8: 0.018113566 | I8: UP | J8: 2.1974623 | K8: 0.00097077923
A9: ENSMUSG00000019577 | B9: Pdk4 | C9: UP | D9: 2.0392029 | E9: 0.0025201256 | F9: UP | G9: 3.2474337 | H9: 0.017939584 | I9: UP | J9: 1.6674253 | K9: 0.045666103
A10: ENSMUSG00000102543 | B10: Pcdhgc5 | C10: UP | D10: 5.6560869 | E10: 6.9661308e-16 | F10: UP | G10: 6.3940792 | H10: 0.0009580985 | I10: UP | J10: 1.306798 | K10: 0.043113474
A11: ENSMUSG00000056476 | B11: Med12l | C11: UP | D11: 2.9044639 | E11: 1.487833e-14 | F11: UP | G11: 4.6092114 | H11: 0.0015560325 | I11: UP | J11: 1.4612157 | K11: 0.0023286848
A12: ENSMUSG00000035606 | B12: Ky | C12: UP | D12: 2.9062651 | E12: 1.2420445e-17 | F12: UP | G12: 2.0249607 | H12: 0.049918594 | I12: UP | J12: 1.4766397 | K12: 0.0079944684
A13: ENSMUSG00000014602 | B13: Kif1a | C13: UP | D13: 2.8541102 | E13: 3.350453e-27 | F13: UP | G13: 2.7438297 | H13: 3.4347388e-09 | I13: UP | J13: 1.0086447 | K13: 0.0018762174
... A29: ENSMUSG00000050556 | B29: Kcnb1 | C29: UP | D29: 2.5654454 | E29: 5.4714045e-19 | F29: UP | G29: 2.3851566 | H29: 0.00039255579 | I29: UP | J29: 1.4059241 | K29: 0.00017650855

Sheet Subgroup3_Aging_and_early_pancr
A1: Ensembl_ID | B1: Symbol | C1: KO_aging_direction | D1: KO_aging_log2FC | E1: KO_aging_padj | F1: WT_aging_direction | G1: WT_aging_log2FC | H1: WT_aging_padj | I1: 14m_genotype_direction | J1: m14_genotype_log2FC | K1: m14_genotype_padj | L1: 6m_genotype_direction | M1: m6_genotype_log2FC | N1: m6_genotype_padj
A2: ENSMUSG00000023089 | B2: Ndufa5 | C2: DOWN | D2: -2.9548334 | E2: 5.1894042e-23 | F2: DOWN | G2: -4.187457 | H2: 6.8737173e-21 | L2: DOWN | M2: -1.5605845 | N2: 6.5664637e-05
A3: ENSMUSG00000029066 | B3: Mrpl20 | C3: DOWN | D3: -2.3785443 | E3: 1.5146454e-18 | F3: DOWN | G3: -3.0790252 | H3: 9.4255288e-17 | L3: DOWN | M3: -1.2646792 | N3: 2.1117449e-05
A4: ENSMUSG00000029397 | B4: Rchy1 | C4: DOWN | D4: -2.1987913 | E4: 7.2064617e-17 | F4: DOWN | G4: -2.4763598 | H4: 1.5799678e-13 | L4: DOWN | M4: -1.1632927 | N4: 7.7990799e-06
A5: ENSMUSG00000029535 | B5: Triap1 | C5: DOWN | D5: -2.6168666 | E5: 3.2372743e-16 | F5: DOWN | G5: -3.1716292 | H5: 5.1009862e-17 | L5: DOWN | M5: -1.169786 | N5: 7.2356362e-05
A6: ENSMUSG00000029642 | B6: Polr1d | C6: DOWN | D6: -2.5999615 | E6: 5.4271157e-30 | F6: DOWN | G6: -3.5316257 | H6: 9.3782824e-41 | L6: DOWN | M6: -1.3126988 | N6: 2.7443617e-07
A7: ENSMUSG00000030335 | B7: Mrpl51 | C7: DOWN | D7: -2.2180465 | E7: 6.7122371e-23 | F7: DOWN | G7: -2.9639295 | H7: 7.3403604e-16 | L7: DOWN | M7: -1.3606071 | N7: 2.8341376e-06
A8: ENSMUSG00000030659 | B8: Nucb2 | C8: DOWN | D8: -2.1991176 | E8: 3.3839118e-34 | F8: DOWN | G8: -2.8486179 | H8: 2.7776199e-27 | L8: DOWN | M8: -1.2401199 | N8: 4.1569972e-07
A9: ENSMUSG00000031059 | B9: Ndufb11 | C9: DOWN | D9: -2.0513595 | E9: 4.5928536e-28 | F9: DOWN | G9: -3.2697828 | H9: 9.1773369e-31 | L9: DOWN | M9: -1.8673841 | N9: 3.6839485e-12
A10: ENSMUSG00000028998 | B10: Tomm7 | C10: DOWN | D10: -2.3878082 | E10: 1.8539558e-21 | F10: DOWN | G10: -3.917512 | H10: 8.3256341e-18 | L10: DOWN | M10: -1.3228494 | N10: 0.00037739237
A11: ENSMUSG00000031231 | B11: Cox7b | C11: DOWN | D11: -2.1827753 | E11: 2.5507188e-17 | F11: DOWN | G11: -2.8849724 | H11: 2.6285147e-21 | L11: DOWN | M11: -1.3202153 | N11: 4.5699283e-06
A12: ENSMUSG00000032330 | B12: Cox7a2 | C12: DOWN | D12: -2.0007555 | E12: 2.5306794e-20 | F12: DOWN | G12: -3.2080798 | H12: 2.2374173e-19 | L12: DOWN | M12: -1.7863767 | N12: 2.0094199e-08
A13: ENSMUSG00000032383 | B13: Ppib | C13: DOWN | D13: -2.7851361 | E13: 4.8159331e-38 | F13: DOWN | G13: -3.1996984 | H13: 9.2287614e-33 | L13: DOWN | M13: -1.2584282 | N13: 5.1216219e-07
... A163: ENSMUSG00000019947 | B163: Arid5b | C163: UP | D163: 3.6176302 | E163: 1.2066848e-30 | F163: UP | G163: 6.8380618 | H163: 5.2692012e-15 | L163: UP | M163: 3.6569427 | N163: 0.0030714754

Sheet Subgroup4_Aging_and_longstandin
A1: Ensembl_ID | B1: Symbol | C1: KO_aging_direction | D1: KO_aging_log2FC | E1: KO_aging_padj | F1: WT_aging_direction | G1: WT_aging_log2FC | H1: WT_aging_padj | I1: 14m_genotype_direction | J1: m14_genotype_log2FC | K1: m14_genotype_padj | L1: 6m_genotype_direction | M1: m6_genotype_log2FC | N1: m6_genotype_padj
A2: ENSMUSG00000075701 | B2: Selenos | C2: DOWN | D2: -2.032774 | E2: 5.5997789e-29 | F2: DOWN | G2: -2.0706664 | H2: 5.9247567e-14 | I2: DOWN | J2: -1.1169858 | K2: 5.3094849e-05 | L2: DOWN | M2: -1.2762743 | N2: 1.0446956e-07
A3: ENSMUSG00000073987 | B3: Ggh | C3: DOWN | D3: -2.536496 | E3: 2.7289946e-31 | F3: DOWN | G3: -2.8148349 | H3: 5.2772503e-19 | I3: DOWN | J3: -2.0538246 | K3: 4.1961863e-12 | L3: DOWN | M3: -2.446206 | N3: 1.1860203e-22
A4: ENSMUSG00000060126 | B4: Tpt1 | C4: DOWN | D4: -2.4883567 | E4: 1.7773929e-65 | F4: DOWN | G4: -3.499586 | H4: 1.5729636e-58 | I4: DOWN | J4: -1.0964336 | K4: 2.7083333e-10 | L4: DOWN | M4: -2.2303945 | N4: 1.6645882e-21
A5: ENSMUSG00000044734 | B5: Serpinb1a | C5: DOWN | D5: -2.433288 | E5: 2.7801315e-23 | F5: DOWN | G5: -2.7248082 | H5: 7.7824445e-30 | I5: DOWN | J5: -2.0702346 | K5: 4.7639442e-13 | L5: DOWN | M5: -2.4832058 | N5: 2.0117239e-27
A6: ENSMUSG00000040205 | B6: Cuzd1 | C6: DOWN | D6: -2.079846 | E6: 4.1059974e-24 | F6: DOWN | G6: -2.4078001 | H6: 6.8067083e-26 | I6: DOWN | J6: -1.2266288 | K6: 3.5784085e-08 | L6: DOWN | M6: -1.6770282 | N6: 4.5696586e-12
A7: ENSMUSG00000034139 | B7: Serpini2 | C7: DOWN | D7: -3.1076397 | E7: 1.6139804e-72 | F7: DOWN | G7: -3.05718 | H7: 5.1741172e-29 | I7: DOWN | J7: -2.7562387 | K7: 2.7646561e-28 | L7: DOWN | M7: -2.8290537 | N7: 1.046949e-47
A8: ENSMUSG00000032575 | B8: Manf | C8: DOWN | D8: -2.4986304 | E8: 2.2560378e-27 | F8: DOWN | G8: -2.4448274 | H8: 2.1208927e-20 | I8: DOWN | J8: -1.1198105 | K8: 1.7315179e-05 | L8: DOWN | M8: -1.184897 | N8: 6.4935642e-05
A9: ENSMUSG00000031919 | B9: Tmed6 | C9: DOWN | D9: -2.4549655 | E9: 1.4517815e-45 | F9: DOWN | G9: -3.4717437 | H9: 4.2337649e-32 | I9: DOWN | J9: -1.2618716 | K9: 5.1168184e-06 | L9: DOWN | M9: -2.4020472 | N9: 2.6615789e-22
A10: ENSMUSG00000024747 | B10: Aldh1a7 | C10: DOWN | D10: -2.4712716 | E10: 4.3307757e-07 | F10: DOWN | G10: -3.1383437 | H10: 4.4503196e-13 | I10: DOWN | J10: -2.1701142 | K10: 0.0011248311 | L10: DOWN | M10: -2.965231 | N10: 5.7728588e-21
A11: ENSMUSG00000023963 | B11: Cyp39a1 | C11: DOWN | D11: -2.6762115 | E11: 6.1797356e-25 | F11: DOWN | G11: -2.4876262 | H11: 3.0183077e-21 | I11: DOWN | J11: -1.8208315 | K11: 2.040675e-08 | L11: DOWN | M11: -1.7674024 | N11: 1.7740375e-12
A12: ENSMUSG00000022270 | B12: Retreg1 | C12: DOWN | D12: -2.6228272 | E12: 5.8075582e-22 | F12: DOWN | G12: -2.0027069 | H12: 1.7934456e-14 | I12: DOWN | J12: -1.6540661 | K12: 3.7506796e-08 | L12: DOWN | M12: -1.1559662 | N12: 1.6330035e-05
A13: ENSMUSG00000022132 | B13: Cldn10 | C13: DOWN | D13: -2.6019525 | E13: 2.6320096e-17 | F13: DOWN | G13: -3.053521 | H13: 2.440602e-21 | I13: DOWN | J13: -1.6109317 | K13: 0.00055401211 | L13: DOWN | M13: -2.169744 | N13: 6.6099696e-17
... A32: ENSMUSG00000037020 | B32: Wdr62 | C32: UP | D32: 2.666108 | E32: 1.1556426e-12 | F32: UP | G32: 3.7897562 | H32: 0.0015856382 | I32: UP | J32: 2.2602999 | K32: 2.2168628e-07 | L32: UP | M32: 3.2565821 | N32: 0.01201128

Sheet Subgroup5_Pancreatitis-specific
A1: Ensembl_ID | B1: Symbol | C1: KO_aging_direction | D1: KO_aging_log2FC | E1: KO_aging_padj | F1: WT_aging_direction | G1: WT_aging_log2FC | H1: WT_aging_padj | I1: 14m_genotype_direction | J1: m14_genotype_log2FC | K1: m14_genotype_padj | L1: 6m_genotype_direction | M1: m6_genotype_log2FC | N1: m6_genotype_padj
A2: ENSMUSG00000022679 | B2: Mpv17l | C2: DOWN | D2: -2.3363751 | E2: 5.835196e-06 | I2: DOWN | J2: -2.609089 | K2: 4.0193408e-05 | L2: DOWN | M2: -2.3637713 | N2: 2.2780935e-11
A3: ENSMUSG00000038146 | B3: Notch3 | C3: UP | D3: 2.2961246 | E3: 2.0987192e-22 | I3: UP | J3: 1.7972342 | K3: 2.8197412e-09 | L3: UP | M3: 1.1995035 | N3: 0.039857343
A4: ENSMUSG00000074818 | B4: Pdzd7 | C4: UP | D4: 2.0616738 | E4: 9.4422803e-09 | I4: UP | J4: 3.5490436 | K4: 1.0858465e-20 | L4: UP | M4: 2.4711851 | N4: 0.00061158154

Sheet Subgroup6_Longstanding_chronic_
A1: Ensembl_ID | B1: Symbol | C1: KO_aging_direction | D1: KO_aging_log2FC | E1: KO_aging_padj | F1: WT_aging_direction | G1: WT_aging_log2FC | H1: WT_aging_padj | I1: 14m_genotype_direction | J1: m14_genotype_log2FC | K1: m14_genotype_padj | L1: 6m_genotype_direction | M1: m6_genotype_log2FC | N1: m6_genotype_padj
A2: ENSMUSG00000089862 | B2: Umad1 | C2: DOWN | D2: -2.296822 | E2: 1.1606254e-08 | I2: DOWN | J2: -1.4920866 | K2: 0.021699368
A3: ENSMUSG00000001627 | B3: Ifrd1 | C3: DOWN | D3: -2.4386406 | E3: 7.6052762e-31 | I3: DOWN | J3: -1.1163543 | K3: 0.00014310644
A4: ENSMUSG00000019872 | B4: Smpdl3a | C4: DOWN | D4: -2.2232201 | E4: 6.6562301e-20 | I4: DOWN | J4: -1.0954188 | K4: 0.0016498092
A5: ENSMUSG00000024640 | B5: Psat1 | C5: DOWN | D5: -2.1544176 | E5: 3.3374225e-22 | I5: DOWN | J5: -1.098916 | K5: 0.00026481071
A6: ENSMUSG00000061273 | B6: Mmgt1 | C6: DOWN | D6: -2.1705903 | E6: 3.6449284e-16 | I6: DOWN | J6: -1.084171 | K6: 0.018253124
A7: ENSMUSG00000045896 | B7: Paip2b | C7: DOWN | D7: -2.2248468 | E7: 2.098979e-28 | I7: DOWN | J7: -1.1395829 | K7: 7.0008147e-05
A8: ENSMUSG00000060002 | B8: Chpt1 | C8: DOWN | D8: -2.1314607 | E8: 1.0783893e-16 | I8: DOWN | J8: -1.0395491 | K8: 0.0033784631
A9: ENSMUSG00000024659 | B9: Anxa1 | C9: DOWN | D9: -2.6426158 | E9: 7.5956152e-20 | I9: DOWN | J9: -1.0006416 | K9: 0.043208389 | L9: UP | M9: 1.5904853 | N9: 1.1418446e-06
A10: ENSMUSG00000059920 | B10: 4930453N24Rik | C10: DOWN | D10: -2.1740914 | E10: 2.7261861e-13 | I10: DOWN | J10: -1.3296751 | K10: 0.0018185
A11: ENSMUSG00000027419 | B11: Pcsk2 | C11: UP | D11: 2.137582 | E11: 1.2108731e-25 | I11: UP | J11: 2.5141244 | K11: 4.2732537e-11
A12: ENSMUSG00000050751 | B12: Pgbd5 | C12: UP | D12: 2.0729494 | E12: 1.5467929e-08 | I12: UP | J12: 5.3673295 | K12: 3.0137914e-09
A13: ENSMUSG00000054728 | B13: Phactr1 | C13: UP | D13: 2.6983801 | E13: 1.2398838e-13 | I13: UP | J13: 1.6586764 | K13: 4.6076448e-05
A14: ENSMUSG00000017316 | B14: Ppy | C14: UP | D14: 3.1523981 | E14: 3.3157269e-32 | I14: UP | J14: 4.0365877 | K14: 2.4714062e-42
A15: ENSMUSG00000015476 | B15: Prrt1 | C15: UP | D15: 2.1930896 | E15: 3.8758674e-07 | I15: UP | J15: 2.353034 | K15: 0.001016532
A16: ENSMUSG00000026204 | B16: Ptprn | C16: UP | D16: 3.4024465 | E16: 7.1350847e-38 | I16: UP | J16: 2.7867279 | K16: 8.1815239e-12
A17: ENSMUSG00000039278 | B17: Pcsk1n | C17: UP | D17: 3.1314214 | E17: 2.8690968e-25 | I17: UP | J17: 3.2189524 | K17: 9.5415293e-19 | L17: DOWN | M17: -1.9183569 | N17: 3.0071901e-07
A18: ENSMUSG00000037095 | B18: Lrg1 | C18: UP | D18: 2.1138724 | E18: 6.336029e-23 | I18: UP | J18: 1.2296011 | K18: 1.6603335e-05
A19: ENSMUSG00000042453 | B19: Reln | C19: UP | D19: 2.7191942 | E19: 1.0402912e-09 | I19: UP | J19: 1.6848945 | K19: 0.023514365
A20: ENSMUSG00000030110 | B20: Ret | C20: UP | D20: 2.2255589 | E20: 8.9100884e-11 | I20: UP | J20: 1.7892614 | K20: 0.0016782614
A21: ENSMUSG00000029420 | B21: Rimbp2 | C21: UP | D21: 4.0423235 | E21: 5.3751795e-34 | I21: UP | J21: 2.1613357 | K21: 1.5600986e-06
A22: ENSMUSG00000037386 | B22: Rims2 | C22: UP | D22: 2.8725802 | E22: 1.5530059e-06 | I22: UP | J22: 2.6567264 | K22: 0.0033784631
A23: ENSMUSG00000032890 | B23: Rims3 | C23: UP | D23: 2.083418 | E23: 2.4363934e-06 | I23: UP | J23: 2.959605 | K23: 7.6071942e-07
A24: ENSMUSG00000022883 | B24: Robo1 | C24: UP | D24: 2.9965131 | E24: 3.6606552e-14 | I24: UP | J24: 1.9344971 | K24: 0.0089430099
A25: ENSMUSG00000017311 | B25: Pyy | C25: UP | D25: 2.7495461 | E25: 3.964908e-26 | F25: DOWN | G25: -2.0387408 | H25: 1.1058958e-05 | I25: UP | J25: 4.1310255 | K25: 4.9281037e-39
A26: ENSMUSG00000053141 | B26: Ptprt | C26: UP | D26: 2.7526396 | E26: 1.0259544e-09 | I26: UP | J26: 2.9864293 | K26: 6.2107432e-07
A27: ENSMUSG00000102312 | B27: Pcdha3 | C27: UP | D27: 7.3237393 | E27: 0.0001404831 | I27: UP | J27: 4.891414 | K27: 0.031198663
A28: ENSMUSG00000052516 | B28: Robo2 | C28: UP | D28: 2.7288178 | E28: 2.0878279e-09 | I28: UP | J28: 2.2362661 | K28: 0.00011395387
A29: ENSMUSG00000028613 | B29: Lrp8 | C29: UP | D29: 3.5385582 | E29: 1.1930457e-11 | I29: UP | J29: 1.6333572 | K29: 0.0086566325
A30: ENSMUSG00000090291 | B30: Lrrc10b | C30: UP | D30: 2.3632081 | E30: 0.0003709738 | I30: UP | J30: 3.6101054 | K30: 0.0054490963
A31: ENSMUSG00000063704 | B31: Mapk15 | C31: UP | D31: 2.0291192 | E31: 1.6940257e-06 | I31: UP | J31: 1.6983589 | K31: 0.0028992304
A32: ENSMUSG00000053693 | B32: Mast1 | C32: UP | D32: 2.3695369 | E32: 1.7193677e-09 | I32: UP | J32: 1.2136962 | K32: 0.011782141
A33: ENSMUSG00000047502 | B33: Mroh7 | C33: UP | D33: 3.1288559 | E33: 6.6916758e-07 | I33: UP | J33: 2.2020628 | K33: 0.0057909503
A34: ENSMUSG00000038916 | B34: Mtcl3 | C34: UP | D34: 4.4141373 | E34: 1.3420283e-09 | I34: UP | J34: 3.9957414 | K34: 0.00049226823
A35: ENSMUSG00000073530 | B35: Pappa2 | C35: UP | D35: 3.2527338 | E35: 1.9413397e-37 | I35: UP | J35: 2.0222638 | K35: 7.7243575e-07
A36: ENSMUSG00000033763 | B36: Mtss2 | C36: UP | D36: 2.2183432 | E36: 1.0898325e-11 | I36: UP | J36: 1.5739902 | K36: 1.3574668e-06
A37: ENSMUSG00000072720 | B37: Myo18b | C37: UP | D37: 6.2647477 | E37: 4.5087625e-07 | I37: UP | J37: 4.3470295 | K37: 0.0045274057
... A51: ENSMUSG00000009246 | B51: Trpm5 | C51: UP | D51: 3.478258 | E51: 6.1675554e-18 | I51: UP | J51: 3.3011342 | K51: 2.2105934e-09
A52: ENSMUSG00000044988 | B52: Ucn3 | C52: UP | D52: 3.0093752 | E52: 2.1424924e-33 | I52: UP | J52: 2.3782379 | K52: 2.5931342e-10 | L52: DOWN | M52: -1.6995225 | N52: 0.0016204196
A53: ENSMUSG00000071234 | B53: Syndig1l | C53: UP | D53: 3.099057 | E53: 4.1186544e-09 | I53: UP | J53: 2.0465871 | K53: 0.0015111857
...

Sheet Subgroup7_Longstanding_chronic_
A1: Ensembl_ID | B1: Symbol | C1: KO_aging_direction | D1: KO_aging_log2FC | E1: KO_aging_padj | F1: WT_aging_direction | G1: WT_aging_log2FC | H1: WT_aging_padj | I1: 14m_genotype_direction | J1: m14_genotype_log2FC | K1: m14_genotype_padj | L1: 6m_genotype_direction | M1: m6_genotype_log2FC | N1: m6_genotype_padj
A2: ENSMUSG00000110344 | B2: Smim36 | C2: DOWN | D2: -3.5855291 | E2: 0.013918491
A3: ENSMUSG00000025059 | B3: Gk | C3: DOWN | D3: -2.6189778 | E3: 0.002245107
A4: ENSMUSG00000025193 | B4: Cutc | C4: DOWN | D4: -2.0975641 | E4: 7.998845e-05
A5: ENSMUSG00000025240 | B5: Sacm1l | C5: DOWN | D5: -2.4360236 | E5: 2.6744632e-17
A6: ENSMUSG00000025451 | B6: Paip1 | C6: DOWN | D6: -2.1560839 | E6: 8.3123734e-21
A7: ENSMUSG00000025607 | B7: Copg2 | C7: DOWN | D7: -2.2408545 | E7: 9.0985636e-18
A8: ENSMUSG00000025613 | B8: Cct8 | C8: DOWN | D8: -2.0295587 | E8: 3.1205672e-30
A9: ENSMUSG00000025666 | B9: Tmem47 | C9: DOWN | D9: -3.2162766 | E9: 4.9381999e-08 | L9: UP | M9: 1.7226187 | N9: 0.024882728
A10: ENSMUSG00000025724 | B10: Sec11a | C10: DOWN | D10: -2.1694404 | E10: 6.424084e-15
A11: ENSMUSG00000025040 | B11: Fundc1 | C11: DOWN | D11: -2.0533259 | E11: 7.552824e-13
A12: ENSMUSG00000025742 | B12: Prps2 | C12: DOWN | D12: -2.1809841 | E12: 1.7593732e-12
A13: ENSMUSG00000025887 | B13: Casp12 | C13: DOWN | D13: -2.5546419 | E13: 5.6654144e-11 | L13: UP | M13: 1.9316125 | N13: 7.0247106e-05
A14: ENSMUSG00000025888 | B14: Casp1 | C14: DOWN | D14: -3.7234869 | E14: 1.8714195e-09
A15: ENSMUSG00000025950 | B15: Idh1 | C15: DOWN | D15: -2.2350851 | E15: 1.9646643e-26
A16: ENSMUSG00000025955 | B16: Akr1cl | C16: DOWN | D16: -2.0976968 | E16: 1.3181176e-07 | I16: UP | J16: 5.8739112 | K16: 0.00062041913 | L16: UP | M16: 8.0411487 | N16: 2.2891967e-06
A17: ENSMUSG00000025981 | B17: Coq10b | C17: DOWN | D17: -2.5846431 | E17: 6.5174413e-10
A18: ENSMUSG00000026005 | B18: Rpe | C18: DOWN | D18: -2.1979265 | E18: 2.4855528e-09
A19: ENSMUSG00000026064 | B19: Ptp4a1 | C19: DOWN | D19: -2.2728348 | E19: 1.0053261e-16
A20: ENSMUSG00000026097 | B20: Ormdl1 | C20: DOWN | D20: -2.9581902 | E20: 2.4232122e-14
A21: ENSMUSG00000025804 | B21: Ccr1 | C21: DOWN | D21: -2.9462957 | E21: 3.2062847e-08
A22: ENSMUSG00000026111 | B22: Unc50 | C22: DOWN | D22: -2.6031252 | E22: 4.1231411e-14
A23: ENSMUSG00000025037 | B23: Maoa | C23: DOWN | D23: -2.2149073 | E23: 5.5155788e-10
A24: ENSMUSG00000024803 | B24: Ankrd1 | C24: DOWN | D24: -2.745737 | E24: 1.5439985e-07 | L24: UP | M24: 3.2055708 | N24: 5.1804506e-07
A25: ENSMUSG00000023156 | B25: Rpp14 | C25: DOWN | D25: -2.2195601 | E25: 1.3547623e-13
A26: ENSMUSG00000023832 | B26: Acat2 | C26: DOWN | D26: -2.6936917 | E26: 8.4082612e-08
A27: ENSMUSG00000023882 | B27: Zfp54 | C27: DOWN | D27: -2.337846 | E27: 0.0033141064
A28: ENSMUSG00000023905 | B28: Tnfrsf12a | C28: DOWN | D28: -3.6431 | E28: 7.5592367e-50 | L28: UP | M28: 2.4929231 | N28: 1.0208045e-10
A29: ENSMUSG00000023913 | B29: Pla2g7 | C29: DOWN | D29: -2.1978659 | E29: 7.3232036e-09 | L29: UP | M29: 1.4976425 | N29: 0.0095402074
A30: ENSMUSG00000023921 | B30: Mmut | C30: DOWN | D30: -2.0618722 | E30: 1.3356075e-16
A31: ENSMUSG00000024056 | B31: Ndc80 | C31: DOWN | D31: -2.9422707 | E31: 0.041718031
A32: ENSMUSG00000024084 | B32: Qpct | C32: DOWN | D32: -2.1516679 | E32: 3.1861167e-07 | L32: UP | M32: 1.4157691 | N32: 0.028616355
A33: ENSMUSG00000025016 | B33: Tm9sf3 | C33: DOWN | D33: -2.3689901 | E33: 8.7364118e-37
A34: ENSMUSG00000024097 | B34: Srsf7 | C34: DOWN | D34: -2.2115133 | E34: 6.1776083e-22
A35: ENSMUSG00000024253 | B35: Dync2li1 | C35: DOWN | D35: -2.0108032 | E35: 2.1130609e-07
A36: ENSMUSG00000024317 | B36: Rnf138 | C36: DOWN | D36: -2.2620071 | E36: 8.5564785e-13
A37: ENSMUSG00000024521 | B37: Pmaip1 | C37: DOWN | D37: -4.1987276 | E37: 2.2970222e-12 | L37: UP | M37: 3.5825632 | N37: 6.1198803e-06
A38: ENSMUSG00000024539 | B38: Ptpn2 | C38: DOWN | D38: -2.2623549 | E38: 1.8354786e-11
A39: ENSMUSG00000024614 | B39: Tmx3 | C39: DOWN | D39: -2.4308716 | E39: 9.2460357e-19 | L39: UP | M39: 1.3009526 | N39: 0.0023981914
A40: ENSMUSG00000024675 | B40: Ms4a4c | C40: DOWN | D40: -2.232243 | E40: 0.030092028
...
